Workbook

Sheet Sheet1
B1: Lampiran Keputusan Direksi PT Bank Pembangunan Daerah Bali Nomor 0118/KEP/DIR/KPN/2023 Tanggal 16 Maret 2023 tentang Check List Kepatuhan dan Pelaksanaan Uji Kepatuhan Dalam Rangka Monitoring
B4: Informasi Pejabat
B5: Nama :
B6: Jabatan :
B7: Unit. :
A9: CHECK LIST KEPATUHAN SEBELUM PERSETUJUAN KREDIT
B11: Cabang / Capem | C11: Tgl File Diterima
B14: I. Informasi Debitur
B16: Nama Pemohon (Debitur / Calon Debitur)
B17: Grup Kelompok Usaha
B18: Alamat Pemohon
B19: Nama Perusahaan/Pemohon (Debitur / Calon Debitur)
B20: Alamat Usaha/Perusahaan
B21: Nama Pemilik/Pengurus Perusahaan
B22: Alamat Pemilik/Pengurus Perusahaan
B23: Jenis Usaha
B24: Plafond
B25: Total fasilitas
B26: Tujuan Penggunaan
B28: II. Persyaratan Administrasi
B29: Pengujian | C29: Checklist | D29: Keterangan / Catatan
B30: KTP Suami/Istri (debitur) yang masih berlaku
B31: KTP seluruh pengurus/persero yang masih berlaku
B32: KTP pemilik jaminan (suami + istri) yang masih berlaku
B33: Kartu Keluarga
B34: Informasi Debitur (iDeb) SLIK OJK suami/istri/pengurus/persero
B35: Daftar Hitam Nasional (DHN) a.n Seluruh Group / Kelompok Usaha Debitur
B36: Appraisal independen
B37: Akuntan Publik
B38: Lainnya :
B39: -
B41: III. Legalitas Usaha
B42: Pengujian | C42: Checklist | D42: Keterangan / Catatan
B43: Akta Pendirian
B44: Akta Perubahan (awal s/d akhir)
B45: Pengesahan
B46: Surat Persetujuan dari Persero/Komisaris
B47: NIB yang masih berlaku (menyesuaikan dengan karakteristik usaha)
B48: NPWP
B49: Surat Keterangan Usaha dari Kepala Desa atau Kelurahan sesuai sektor usaha
...

Sheet Sheet3
A1: Unit | B1: Ketentuan | C1: Terpenuhi | D1: Tdk terpenuhi
A2: Teller | B2: cek… | C2: 1
B3: cek… | C3: 1
B4: cek… | D4: 1
B5: cek… | C5: 1
B6: Total | C6: =SUM(C2:C5) -> 3 | D6: =SUM(D2:D5) -> 1
C7: =C6/(C6+D6) -> 0.75 | D7: =D6/(C6+D6) -> 0.25

Sheet Sheet2
A1: PERHITUNGAN AGUNAN
A3: No. | B3: Agunan | C3: Taksasi | D3: CEF | E3: CEV
A4: 1. | B4: Controlled
B5: =Sheet1!D65 | C5: =1500000*200 -> 300000000 | D5: 0.75 | E5: =C5*D5 -> 225000000
B6: Bangunan | C6: 465000000 | D6: 0.4 | E6: =C6*D6 -> 186000000
B7: Penjaminan suami | C7: =300000000*70% -> 210000000 | D7: 1 | E7: =C7*D7 -> 210000000
B8: Penjaminan istri | D8: 1 | E8: =C8*D8 -> 0
B9: Persentase Thd Plafond | C9: =(C5+C7+C8+C6)/Sheet1!D25 -> #DIV/0! | E9: =(E5+E6+E7)/Sheet1!D25 -> #DIV/0!
B10: Persentase Thd Baki Debet
A12: 2. | B12: Uncontrolled
B13: Persediaan | C13: 0 | D13: 0.5 | E13: =C13*D13 -> 0
B14: Persentase Thd Plafond | C14: =C13/[1]Sheet1!$D$18 -> #ERROR! | E14: =E13/[1]Sheet1!$D$18 -> #ERROR!
B15: Persentase Thd Baki Debet | C15: =C13/[1]Sheet1!$D$18 -> #ERROR! | E15: =E13/[1]Sheet1!$D$18 -> #ERROR!
B17: Total Controlled + Uncontrolled | C17: =C5+C13+C7+C8 -> 510000000 | E17: =E5+E7+E8 -> 435000000
B18: Persentase Thd Plafond | C18: =C17/Sheet1!D24 -> #DIV/0! | E18: =(E5+E7+E8)/Sheet1!D24 -> #DIV/0!
B19: Persentase Thd Baki Debet
B21: Persentase masing-masing fasilitas | C21: KUR suami | E21: KUR ybs
B22: HT | C22: 625000 | E22: 375000
B23: %tase thp plafond | C23: =C22/500000 -> 1.25 | E23: =E22/300000 -> 1.25
B24: CEV Controlled | C24: 844104 | E24: 530963
B25: %tase thp plafond | C25: =C24/500000 -> 1.688208 | E25: =E24/300000 -> 1.7698767
B26: CEV Uncontrolled | C26: 0 | E26: 623997
B27: %tase thp plafond | C27: 0 | E27: =E26/300000 -> 2.07999
B28: Total CEV | C28: =C24+C27 -> 844104 | E28: =E24+E26 -> 1154960
B29: %tase total CEV | C29: =C28/500000 -> 1.688208 | E29: =E28/300000 -> 3.8498667
